Traceback (most recent call last):
  File "/usr/share/miniconda/envs/phys141/lib/python3.9/site-packages/jupyter_cache/executors/utils.py", line 58, in single_nb_execution
    executenb(
  File "/usr/share/miniconda/envs/phys141/lib/python3.9/site-packages/nbclient/client.py", line 1305, in execute
    return NotebookClient(nb=nb, resources=resources, km=km, **kwargs).execute()
  File "/usr/share/miniconda/envs/phys141/lib/python3.9/site-packages/jupyter_core/utils/__init__.py", line 166, in wrapped
    return loop.run_until_complete(inner)
  File "/usr/share/miniconda/envs/phys141/lib/python3.9/asyncio/base_events.py", line 647, in run_until_complete
    return future.result()
  File "/usr/share/miniconda/envs/phys141/lib/python3.9/site-packages/nbclient/client.py", line 705, in async_execute
    await self.async_execute_cell(
  File "/usr/share/miniconda/envs/phys141/lib/python3.9/site-packages/nbclient/client.py", line 1058, in async_execute_cell
    await self._check_raise_for_error(cell, cell_index, exec_reply)
  File "/usr/share/miniconda/envs/phys141/lib/python3.9/site-packages/nbclient/client.py", line 914, in _check_raise_for_error
    raise CellExecutionError.from_cell_and_msg(cell, exec_reply_content)
nbclient.exceptions.CellExecutionError: An error occurred while executing the following cell:
------------------
import sys
sys.path.insert(0,'/home/jovyan/nemo')
import nemo_start
------------------


[0;31m---------------------------------------------------------------------------[0m
[0;31mModuleNotFoundError[0m                       Traceback (most recent call last)
Cell [0;32mIn[1], line 3[0m
[1;32m      1[0m [38;5;28;01mimport[39;00m [38;5;21;01msys[39;00m
[1;32m      2[0m sys[38;5;241m.[39mpath[38;5;241m.[39minsert([38;5;241m0[39m,[38;5;124m'[39m[38;5;124m/home/jovyan/nemo[39m[38;5;124m'[39m)
[0;32m----> 3[0m [38;5;28;01mimport[39;00m [38;5;21;01mnemo_start[39;00m

[0;31mModuleNotFoundError[0m: No module named 'nemo_start'

